Workbook

Sheet Product Catalogue
A1: PRODUCT CATALOGUE
A2: Mapped SKU | B2: Supplier Product Name | C2: Mapped Category | D2: Subcategory | E2: Product Type | F2: Supplier | G2: Specification | H2: Unit | I2: Price | J2: Currency | K2: Country of Origin | L2: Status
A3: BIO-PKS-001 | B3: Palm Kernel Shells – Standard | C3: Biomass | D3: Palm Kernel Shells | E3: Standard Grade | F3: Supplier A | G3: Moisture ≤15%; Ash ≤5% | H3: MT | I3: 85 | J3: USD | K3: Nigeria | L3: Active
A4: BIO-PKS-002 | B4: Palm Kernel Shells – Premium | C4: Biomass | D4: Palm Kernel Shells | E4: Premium Grade | F4: Supplier B | G4: Moisture ≤12%; Ash ≤4% | H4: MT | I4: 105 | J4: USD | K4: Nigeria | L4: Active
A5: BIO-WOD-001 | B5: Industrial Wood Pellets | C5: Biomass | D5: Wood Pellets | E5: Industrial Grade | F5: Supplier C | G5: 6mm; Moisture ≤10% | H5: MT | I5: 145 | J5: EUR | K5: Ukraine | L5: Active
A6: BIO-WOD-002 | B6: Premium Wood Pellets | C6: Biomass | D6: Wood Pellets | E6: Premium Grade | F6: Supplier D | G6: 8mm; Moisture ≤8% | H6: MT | I6: 175 | J6: EUR | K6: Latvia | L6: Active
A7: BIO-SAW-001 | B7: Dry Sawdust | C7: Biomass | D7: Sawdust | E7: Dry Grade | F7: Supplier A | G7: Moisture ≤12% | H7: MT | I7: 70 | J7: USD | K7: Nigeria | L7: Active
A8: BIO-BRI-001 | B8: Biomass Briquettes | C8: Biomass | D8: Briquettes | E8: Biomass Briquette | F8: Supplier E | G8: 70mm; Moisture ≤10% | H8: MT | I8: 120 | J8: USD | K8: Nigeria | L8: Active
A9: OIL-SUN-001 | B9: Crude Sunflower Oil | C9: Oils & Fats | D9: Sunflower Oil | E9: Crude Oil | F9: Supplier F | G9: FFA ≤2%; Moisture ≤0.2% | H9: MT | I9: 920 | J9: USD | K9: Ukraine | L9: Active
A10: OIL-SUN-002 | B10: Refined Sunflower Oil | C10: Oils & Fats | D10: Sunflower Oil | E10: Refined Oil | F10: Supplier G | G10: Food Grade; RBD | H10: MT | I10: 1080 | J10: USD | K10: Turkey | L10: Active
A11: OIL-SOY-001 | B11: Crude Soybean Oil | C11: Oils & Fats | D11: Soybean Oil | E11: Crude Oil | F11: Supplier H | G11: FFA ≤1.5% | H11: MT | I11: 950 | J11: USD | K11: Brazil | L11: Active
A12: OIL-PAL-001 | B12: Crude Palm Oil | C12: Oils & Fats | D12: Palm Oil | E12: Crude Palm Oil | F12: Supplier I | G12: FFA ≤5% | H12: MT | I12: 900 | J12: USD | K12: Malaysia | L12: Active
A13: OIL-SHE-001 | B13: Natural Shea Butter | C13: Oils & Fats | D13: Shea Products | E13: Unrefined Shea Butter | F13: Supplier J | G13: Unrefined; Cosmetic Grade | H13: MT | I13: 1850 | J13: USD | K13: Nigeria | L13: Active
A14: OIL-SHE-002 | B14: Refined Shea Butter | C14: Oils & Fats | D14: Shea Products | E14: Refined Shea Butter | F14: Supplier C | G14: Refined; Cosmetic Grade | H14: MT | I14: 2100 | J14: USD | K14: Nigeria | L14: Active
... A52: LEG-SOY-001 | B52: Soybeans | C52: Food Commodities | D52: Legumes | E52: Soybeans | F52: Supplier A | G52: Non-GMO; Feed Grade | H52: MT | I52: 420 | J52: USD | K52: Nigeria | L52: Active

Sheet Duplicate Review
A1: Product 1 SKU | B1: Product 1 Name | C1: Product 2 SKU | D1: Product 2 Name | E1: Duplicate Reason | F1: Review Status
A2: ='Product Catalogue'!A16 -> SUG-ICU-001 | B2: ='Product Catalogue'!B16 -> ICUMSA 45 Sugar | C2: ='Product Catalogue'!A17 -> SUG-ICU-002 | D2: ='Product Catalogue'!B17 -> Refined White Sugar IC45 | E2: Same product specification and packaging different supplier/product name | F2: Pending Review
A3: ='Product Catalogue'!A38 -> PAC-BAG-002 | B3: ='Product Catalogue'!B38 -> PP Woven Bags | C3: ='Product Catalogue'!A39 -> PAC-JUM-001 | D3: ='Product Catalogue'!B39 -> FIBC Jumbo Bag | E3: Same FIBC type and 1 MT SWL specification; different product name | F3: Pending Review
A4: ='Product Catalogue'!A47 -> TEX-COT-002 | B4: ='Product Catalogue'!B47 -> Cotton Lint | C4: ='Product Catalogue'!A48 -> GRA-MAI-001 | D4: ='Product Catalogue'!B48 -> Maize | E4: Same yellow maize/feed-grade specification; different product name | F4: Pending Review

Sheet Taxonomy
A1: Mapped Category | B1: Subcategory | C1: Product Type
A2: ='Product Catalogue'!C3 -> Biomass | B2: ='Product Catalogue'!D3 -> Palm Kernel Shells | C2: ='Product Catalogue'!E3 -> Standard Grade
A3: ='Product Catalogue'!C4 -> Biomass | B3: ='Product Catalogue'!D4 -> Palm Kernel Shells | C3: ='Product Catalogue'!E4 -> Premium Grade
A4: ='Product Catalogue'!C5 -> Biomass | B4: ='Product Catalogue'!D5 -> Wood Pellets | C4: ='Product Catalogue'!E5 -> Industrial Grade
A5: ='Product Catalogue'!C6 -> Biomass | B5: ='Product Catalogue'!D6 -> Wood Pellets | C5: ='Product Catalogue'!E6 -> Premium Grade
A6: ='Product Catalogue'!C7 -> Biomass | B6: ='Product Catalogue'!D7 -> Sawdust | C6: ='Product Catalogue'!E7 -> Dry Grade
A7: ='Product Catalogue'!C8 -> Biomass | B7: ='Product Catalogue'!D8 -> Briquettes | C7: ='Product Catalogue'!E8 -> Biomass Briquette
A8: ='Product Catalogue'!C9 -> Oils & Fats | B8: ='Product Catalogue'!D9 -> Sunflower Oil | C8: ='Product Catalogue'!E9 -> Crude Oil
A9: ='Product Catalogue'!C10 -> Oils & Fats | B9: ='Product Catalogue'!D10 -> Sunflower Oil | C9: ='Product Catalogue'!E10 -> Refined Oil
A10: ='Product Catalogue'!C11 -> Oils & Fats | B10: ='Product Catalogue'!D11 -> Soybean Oil | C10: ='Product Catalogue'!E11 -> Crude Oil
A11: ='Product Catalogue'!C12 -> Oils & Fats | B11: ='Product Catalogue'!D12 -> Palm Oil | C11: ='Product Catalogue'!E12 -> Crude Palm Oil
A12: ='Product Catalogue'!C13 -> Oils & Fats | B12: ='Product Catalogue'!D13 -> Shea Products | C12: ='Product Catalogue'!E13 -> Unrefined Shea Butter
A13: ='Product Catalogue'!C14 -> Oils & Fats | B13: ='Product Catalogue'!D14 -> Shea Products | C13: ='Product Catalogue'!E14 -> Refined Shea Butter
... A15: ='Product Catalogue'!C16 -> Food Commodities | B15: ='Product Catalogue'!D16 -> Sugar | C15: ='Product Catalogue'!E16 -> Refined White Sugar
A16: ='Product Catalogue'!C19 -> Food Commodities | B16: ='Product Catalogue'!D19 -> Sugar | C16: ='Product Catalogue'!E19 -> Raw Sugar
A17: ='Product Catalogue'!C20 -> Food Commodities | B17: ='Product Catalogue'!D20 -> Rice | C17: ='Product Catalogue'!E20 -> Long Grain
A18: ='Product Catalogue'!C21 -> Food Commodities | B18: ='Product Catalogue'!D21 -> Rice | C18: ='Product Catalogue'!E21 -> Parboiled Long Grain
A19: ='Product Catalogue'!C22 -> Food Commodities | B19: ='Product Catalogue'!D22 -> Rice | C19: ='Product Catalogue'!E22 -> Basmati
A20: ='Product Catalogue'!C23 -> Agricultural Products | B20: ='Product Catalogue'!D23 -> Cashew | C20: ='Product Catalogue'!E23 -> Raw Cashew Nuts
A21: ='Product Catalogue'!C25 -> Agricultural Products | B21: ='Product Catalogue'!D25 -> Sesame | C21: ='Product Catalogue'!E25 -> Natural Sesame
A22: ='Product Catalogue'!C26 -> Agricultural Products | B22: ='Product Catalogue'!D26 -> Sesame | C22: ='Product Catalogue'!E26 -> Hulled Sesame
A23: ='Product Catalogue'!C27 -> Agricultural Products | B23: ='Product Catalogue'!D27 -> Coconut | C23: ='Product Catalogue'!E27 -> Dried Coconut
A24: ='Product Catalogue'!C28 -> Agricultural Products | B24: ='Product Catalogue'!D28 -> Coconut | C24: ='Product Catalogue'!E28 -> Desiccated Coconut
A25: ='Product Catalogue'!C29 -> Agricultural Products | B25: ='Product Catalogue'!D29 -> Cocoa | C25: ='Product Catalogue'!E29 -> Fermented Cocoa Beans
A26: ='Product Catalogue'!C31 -> Agricultural Products | B26: ='Product Catalogue'!D31 -> Spices | C26: ='Product Catalogue'!E31 -> Whole Dried Ginger
A27: ='Product Catalogue'!C32 -> Agricultural Products | B27: ='Product Catalogue'!D32 -> Spices | C27: ='Product Catalogue'!E32 -> Ginger Powder
A28: ='Product Catalogue'!C33 -> Minerals & Metals | B28: ='Product Catalogue'!D33 -> Gold | C28: ='Product Catalogue'!E33 -> Gold Bar
A29: ='Product Catalogue'!C34 -> Minerals & Metals | B29: ='Product Catalogue'!D34 -> Gold | C29: ='Product Catalogue'!E34 -> Gold Nugget
A30: ='Product Catalogue'!C35 -> Minerals & Metals | B30: ='Product Catalogue'!D35 -> Aluminium | C30: ='Product Catalogue'!E35 -> Aluminium Ingot
A31: ='Product Catalogue'!C36 -> Minerals & Metals | B31: ='Product Catalogue'!D36 -> Copper | C31: ='Product Catalogue'!E36 -> Copper Cathode
A32: ='Product Catalogue'!C37 -> Packaging | B32: ='Product Catalogue'!D37 -> Bags | C32: ='Product Catalogue'!E37 -> Woven PP Bag
A33: ='Product Catalogue'!C38 -> Packaging | B33: ='Product Catalogue'!D38 -> Bags | C33: ='Product Catalogue'!E38 -> Printed Woven PP Bag
A34: ='Product Catalogue'!C39 -> Packaging | B34: ='Product Catalogue'!D39 -> Jumbo Bags | C34: ='Product Catalogue'!E39 -> FIBC Jumbo Bag
A35: ='Product Catalogue'!C41 -> Industrial Materials | B35: ='Product Catalogue'!D41 -> Caustic Soda | C35: ='Product Catalogue'!E41 -> Caustic Soda Flakes
A36: ='Product Catalogue'!C42 -> Industrial Materials | B36: ='Product Catalogue'!D42 -> Sodium Products | C36: ='Product Catalogue'!E42 -> Soda Ash Light
A37: ='Product Catalogue'!C43 -> Industrial Materials | B37: ='Product Catalogue'!D43 -> Sodium Products | C37: ='Product Catalogue'!E43 -> Soda Ash Dense
A38: ='Product Catalogue'!C44 -> Paper & Pulp | B38: ='Product Catalogue'!D44 -> Wood Pulp | C38: ='Product Catalogue'!E44 -> Bleached Kraft Pulp
A39: ='Product Catalogue'!C45 -> Paper & Pulp | B39: ='Product Catalogue'!D45 -> Wood Pulp | C39: ='Product Catalogue'!E45 -> Hardwood Kraft Pulp
A40: ='Product Catalogue'!C46 -> Textiles | B40: ='Product Catalogue'!D46 -> Cotton | C40: ='Product Catalogue'!E46 -> Raw Cotton
A41: ='Product Catalogue'!C47 -> Textiles | B41: ='Product Catalogue'!D47 -> Cotton | C41: ='Product Catalogue'!E47 -> Cotton Lint
...

Sheet Supplier Mapping
A1: Supplier | B1: Supplier Product Name | C1: Mapped SKU | D1: Mapped Category
A2: ='Product Catalogue'!F3 -> Supplier A | B2: ='Product Catalogue'!B3 -> Palm Kernel Shells – Standard | C2: ='Product Catalogue'!A3 -> BIO-PKS-001 | D2: ='Product Catalogue'!C3 -> Biomass
A3: ='Product Catalogue'!F4 -> Supplier B | B3: ='Product Catalogue'!B4 -> Palm Kernel Shells – Premium | C3: ='Product Catalogue'!A4 -> BIO-PKS-002 | D3: ='Product Catalogue'!C4 -> Biomass
A4: ='Product Catalogue'!F5 -> Supplier C | B4: ='Product Catalogue'!B5 -> Industrial Wood Pellets | C4: ='Product Catalogue'!A5 -> BIO-WOD-001 | D4: ='Product Catalogue'!C5 -> Biomass
A5: ='Product Catalogue'!F6 -> Supplier D | B5: ='Product Catalogue'!B6 -> Premium Wood Pellets | C5: ='Product Catalogue'!A6 -> BIO-WOD-002 | D5: ='Product Catalogue'!C6 -> Biomass
A6: ='Product Catalogue'!F7 -> Supplier A | B6: ='Product Catalogue'!B7 -> Dry Sawdust | C6: ='Product Catalogue'!A7 -> BIO-SAW-001 | D6: ='Product Catalogue'!C7 -> Biomass
A7: ='Product Catalogue'!F8 -> Supplier E | B7: ='Product Catalogue'!B8 -> Biomass Briquettes | C7: ='Product Catalogue'!A8 -> BIO-BRI-001 | D7: ='Product Catalogue'!C8 -> Biomass
A8: ='Product Catalogue'!F9 -> Supplier F | B8: ='Product Catalogue'!B9 -> Crude Sunflower Oil | C8: ='Product Catalogue'!A9 -> OIL-SUN-001 | D8: ='Product Catalogue'!C9 -> Oils & Fats
A9: ='Product Catalogue'!F10 -> Supplier G | B9: ='Product Catalogue'!B10 -> Refined Sunflower Oil | C9: ='Product Catalogue'!A10 -> OIL-SUN-002 | D9: ='Product Catalogue'!C10 -> Oils & Fats
A10: ='Product Catalogue'!F11 -> Supplier H | B10: ='Product Catalogue'!B11 -> Crude Soybean Oil | C10: ='Product Catalogue'!A11 -> OIL-SOY-001 | D10: ='Product Catalogue'!C11 -> Oils & Fats
A11: ='Product Catalogue'!F12 -> Supplier I | B11: ='Product Catalogue'!B12 -> Crude Palm Oil | C11: ='Product Catalogue'!A12 -> OIL-PAL-001 | D11: ='Product Catalogue'!C12 -> Oils & Fats
A12: ='Product Catalogue'!F13 -> Supplier J | B12: ='Product Catalogue'!B13 -> Natural Shea Butter | C12: ='Product Catalogue'!A13 -> OIL-SHE-001 | D12: ='Product Catalogue'!C13 -> Oils & Fats
A13: ='Product Catalogue'!F14 -> Supplier C | B13: ='Product Catalogue'!B14 -> Refined Shea Butter | C13: ='Product Catalogue'!A14 -> OIL-SHE-002 | D13: ='Product Catalogue'!C14 -> Oils & Fats
... A51: ='Product Catalogue'!F52 -> Supplier A | B51: ='Product Catalogue'!B52 -> Soybeans | C51: ='Product Catalogue'!A52 -> LEG-SOY-001 | D51: ='Product Catalogue'!C52 -> Food Commodities

Sheet Data Quality
A1: Data Quality Rule | B1: Requirement | C1: Validation Method | D1: Status
A2: Mapped SKU | B2: Must match the master Product Catalogue SKU | C2: Lookup validation | D2: Active
A3: Supplier Product Name | B3: Clear and standardized product name | C3: Text review | D3: Active
A4: Mapped Category | B4: Must match the approved taxonomy | C4: Taxonomy lookup | D4: Active
A5: Subcategory | B5: Must belong to the selected category | C5: Taxonomy validation | D5: Active
A6: Product Type | B6: Must match the approved product clasification | C6: Taxonomy validation | D6: Active
A7: Supplier | B7: Must be linked to an approved supplier | C7: Supplier validation | D7: Active
A8: Specification | B8: Required technical details must be complete | C8: Completeness Check | D8: Active
A9: Unit | B9: Must use standardized units such MT, kg or PCS | C9: Dropdown validation | D9: Active
A10: Price | B10: Must be numeric and greater than zero | C10: Numeric validation | D10: Active
A11: Currency | B11: Must use an approved currency code | C11: Dropdown validation | D11: Active
A12: Country of Origin | B12: Must be completed and valid | C12: Data completeness Check | D12: Active
A13: Status | B13: Must use approved status values | C13: Dropdown validation | D13: Active

Sheet PIM Data Management
A1: Mapped SKU | B1: Supplier Product Name | C1: Mapped Category | D1: Subcategory | E1: Product Type | F1: Supplier | G1: Specification | H1: Status | I1: Data Completeness | J1: Specification Check | K1: Taxonomy Check | L1: Overall Quality Status | N1: PIM Data Quality Summary
A2: ='Product Catalogue'!A3 -> BIO-PKS-001 | B2: ='Product Catalogue'!B3 -> Palm Kernel Shells – Standard | C2: ='Product Catalogue'!C3 -> Biomass | D2: ='Product Catalogue'!D3 -> Palm Kernel Shells | E2: ='Product Catalogue'!E3 -> Standard Grade | F2: ='Product Catalogue'!F3 -> Supplier A | G2: ='Product Catalogue'!G3 -> Moisture ≤15%; Ash ≤5% | H2: ='Product Catalogue'!L3 -> Active | I2: =IF(COUNTA(A2:H2)=8,"Complete","Incomplete") -> Complete | J2: =IF(G2<>"","Pass","Fail") -> Pass | K2: =IF(AND(C2<>"",D2<>"",E2<>""),"Pass","Fail") -> Pass | L2: =IF(AND(I2="Complete",J2="Pass",K2="Pass"),"Approved","Review Required") -> Approved | N2: Total Products | O2: =COUNTA(A2:A51) -> 50
A3: ='Product Catalogue'!A4 -> BIO-PKS-002 | B3: ='Product Catalogue'!B4 -> Palm Kernel Shells – Premium | C3: ='Product Catalogue'!C4 -> Biomass | D3: ='Product Catalogue'!D4 -> Palm Kernel Shells | E3: ='Product Catalogue'!E4 -> Premium Grade | F3: ='Product Catalogue'!F4 -> Supplier B | G3: ='Product Catalogue'!G4 -> Moisture ≤12%; Ash ≤4% | H3: ='Product Catalogue'!L4 -> Active | I3: =IF(COUNTA(A3:H3)=8,"Complete","Incomplete") -> Complete | J3: =IF(G3<>"","Pass","Fail") -> Pass | K3: =IF(AND(C3<>"",D3<>"",E3<>""),"Pass","Fail") -> Pass | L3: =IF(AND(I3="Complete",J3="Pass",K3="Pass"),"Approved","Review Required") -> Approved | N3: Complete Records | O3: =COUNTIF(I2:I51,"Complete") -> 50
A4: ='Product Catalogue'!A5 -> BIO-WOD-001 | B4: ='Product Catalogue'!B5 -> Industrial Wood Pellets | C4: ='Product Catalogue'!C5 -> Biomass | D4: ='Product Catalogue'!D5 -> Wood Pellets | E4: ='Product Catalogue'!E5 -> Industrial Grade | F4: ='Product Catalogue'!F5 -> Supplier C | G4: ='Product Catalogue'!G5 -> 6mm; Moisture ≤10% | H4: ='Product Catalogue'!L5 -> Active | I4: =IF(COUNTA(A4:H4)=8,"Complete","Incomplete") -> Complete | J4: =IF(G4<>"","Pass","Fail") -> Pass | K4: =IF(AND(C4<>"",D4<>"",E4<>""),"Pass","Fail") -> Pass | L4: =IF(AND(I4="Complete",J4="Pass",K4="Pass"),"Approved","Review Required") -> Approved | N4: Specification Pass | O4: =COUNTIF(J2:J51,"Pass") -> 50
A5: ='Product Catalogue'!A6 -> BIO-WOD-002 | B5: ='Product Catalogue'!B6 -> Premium Wood Pellets | C5: ='Product Catalogue'!C6 -> Biomass | D5: ='Product Catalogue'!D6 -> Wood Pellets | E5: ='Product Catalogue'!E6 -> Premium Grade | F5: ='Product Catalogue'!F6 -> Supplier D | G5: ='Product Catalogue'!G6 -> 8mm; Moisture ≤8% | H5: ='Product Catalogue'!L6 -> Active | I5: =IF(COUNTA(A5:H5)=8,"Complete","Incomplete") -> Complete | J5: =IF(G5<>"","Pass","Fail") -> Pass | K5: =IF(AND(C5<>"",D5<>"",E5<>""),"Pass","Fail") -> Pass | L5: =IF(AND(I5="Complete",J5="Pass",K5="Pass"),"Approved","Review Required") -> Approved | N5: Taxonomy Pass | O5: =COUNTIF(K2:K51,"Pass") -> 50
A6: ='Product Catalogue'!A7 -> BIO-SAW-001 | B6: ='Product Catalogue'!B7 -> Dry Sawdust | C6: ='Product Catalogue'!C7 -> Biomass | D6: ='Product Catalogue'!D7 -> Sawdust | E6: ='Product Catalogue'!E7 -> Dry Grade | F6: ='Product Catalogue'!F7 -> Supplier A | G6: ='Product Catalogue'!G7 -> Moisture ≤12% | H6: ='Product Catalogue'!L7 -> Active | I6: =IF(COUNTA(A6:H6)=8,"Complete","Incomplete") -> Complete | J6: =IF(G6<>"","Pass","Fail") -> Pass | K6: =IF(AND(C6<>"",D6<>"",E6<>""),"Pass","Fail") -> Pass | L6: =IF(AND(I6="Complete",J6="Pass",K6="Pass"),"Approved","Review Required") -> Approved | N6: Approved Records | O6: =COUNTIF(L2:L51,"Approved") -> 50
A7: ='Product Catalogue'!A8 -> BIO-BRI-001 | B7: ='Product Catalogue'!B8 -> Biomass Briquettes | C7: ='Product Catalogue'!C8 -> Biomass | D7: ='Product Catalogue'!D8 -> Briquettes | E7: ='Product Catalogue'!E8 -> Biomass Briquette | F7: ='Product Catalogue'!F8 -> Supplier E | G7: ='Product Catalogue'!G8 -> 70mm; Moisture ≤10% | H7: ='Product Catalogue'!L8 -> Active | I7: =IF(COUNTA(A7:H7)=8,"Complete","Incomplete") -> Complete | J7: =IF(G7<>"","Pass","Fail") -> Pass | K7: =IF(AND(C7<>"",D7<>"",E7<>""),"Pass","Fail") -> Pass | L7: =IF(AND(I7="Complete",J7="Pass",K7="Pass"),"Approved","Review Required") -> Approved | N7: Review Required | O7: =COUNTIF(L2:L51,"Review Required") -> 0
A8: ='Product Catalogue'!A9 -> OIL-SUN-001 | B8: ='Product Catalogue'!B9 -> Crude Sunflower Oil | C8: ='Product Catalogue'!C9 -> Oils & Fats | D8: ='Product Catalogue'!D9 -> Sunflower Oil | E8: ='Product Catalogue'!E9 -> Crude Oil | F8: ='Product Catalogue'!F9 -> Supplier F | G8: ='Product Catalogue'!G9 -> FFA ≤2%; Moisture ≤0.2% | H8: ='Product Catalogue'!L9 -> Active | I8: =IF(COUNTA(A8:H8)=8,"Complete","Incomplete") -> Complete | J8: =IF(G8<>"","Pass","Fail") -> Pass | K8: =IF(AND(C8<>"",D8<>"",E8<>""),"Pass","Fail") -> Pass | L8: =IF(AND(I8="Complete",J8="Pass",K8="Pass"),"Approved","Review Required") -> Approved
A9: ='Product Catalogue'!A10 -> OIL-SUN-002 | B9: ='Product Catalogue'!B10 -> Refined Sunflower Oil | C9: ='Product Catalogue'!C10 -> Oils & Fats | D9: ='Product Catalogue'!D10 -> Sunflower Oil | E9: ='Product Catalogue'!E10 -> Refined Oil | F9: ='Product Catalogue'!F10 -> Supplier G | G9: ='Product Catalogue'!G10 -> Food Grade; RBD | H9: ='Product Catalogue'!L10 -> Active | I9: =IF(COUNTA(A9:H9)=8,"Complete","Incomplete") -> Complete | J9: =IF(G9<>"","Pass","Fail") -> Pass | K9: =IF(AND(C9<>"",D9<>"",E9<>""),"Pass","Fail") -> Pass | L9: =IF(AND(I9="Complete",J9="Pass",K9="Pass"),"Approved","Review Required") -> Approved
A10: ='Product Catalogue'!A11 -> OIL-SOY-001 | B10: ='Product Catalogue'!B11 -> Crude Soybean Oil | C10: ='Product Catalogue'!C11 -> Oils & Fats | D10: ='Product Catalogue'!D11 -> Soybean Oil | E10: ='Product Catalogue'!E11 -> Crude Oil | F10: ='Product Catalogue'!F11 -> Supplier H | G10: ='Product Catalogue'!G11 -> FFA ≤1.5% | H10: ='Product Catalogue'!L11 -> Active | I10: =IF(COUNTA(A10:H10)=8,"Complete","Incomplete") -> Complete | J10: =IF(G10<>"","Pass","Fail") -> Pass | K10: =IF(AND(C10<>"",D10<>"",E10<>""),"Pass","Fail") -> Pass | L10: =IF(AND(I10="Complete",J10="Pass",K10="Pass"),"Approved","Review Required") -> Approved
A11: ='Product Catalogue'!A12 -> OIL-PAL-001 | B11: ='Product Catalogue'!B12 -> Crude Palm Oil | C11: ='Product Catalogue'!C12 -> Oils & Fats | D11: ='Product Catalogue'!D12 -> Palm Oil | E11: ='Product Catalogue'!E12 -> Crude Palm Oil | F11: ='Product Catalogue'!F12 -> Supplier I | G11: ='Product Catalogue'!G12 -> FFA ≤5% | H11: ='Product Catalogue'!L12 -> Active | I11: =IF(COUNTA(A11:H11)=8,"Complete","Incomplete") -> Complete | J11: =IF(G11<>"","Pass","Fail") -> Pass | K11: =IF(AND(C11<>"",D11<>"",E11<>""),"Pass","Fail") -> Pass | L11: =IF(AND(I11="Complete",J11="Pass",K11="Pass"),"Approved","Review Required") -> Approved
A12: ='Product Catalogue'!A13 -> OIL-SHE-001 | B12: ='Product Catalogue'!B13 -> Natural Shea Butter | C12: ='Product Catalogue'!C13 -> Oils & Fats | D12: ='Product Catalogue'!D13 -> Shea Products | E12: ='Product Catalogue'!E13 -> Unrefined Shea Butter | F12: ='Product Catalogue'!F13 -> Supplier J | G12: ='Product Catalogue'!G13 -> Unrefined; Cosmetic Grade | H12: ='Product Catalogue'!L13 -> Active | I12: =IF(COUNTA(A12:H12)=8,"Complete","Incomplete") -> Complete | J12: =IF(G12<>"","Pass","Fail") -> Pass | K12: =IF(AND(C12<>"",D12<>"",E12<>""),"Pass","Fail") -> Pass | L12: =IF(AND(I12="Complete",J12="Pass",K12="Pass"),"Approved","Review Required") -> Approved
A13: ='Product Catalogue'!A14 -> OIL-SHE-002 | B13: ='Product Catalogue'!B14 -> Refined Shea Butter | C13: ='Product Catalogue'!C14 -> Oils & Fats | D13: ='Product Catalogue'!D14 -> Shea Products | E13: ='Product Catalogue'!E14 -> Refined Shea Butter | F13: ='Product Catalogue'!F14 -> Supplier C | G13: ='Product Catalogue'!G14 -> Refined; Cosmetic Grade | H13: ='Product Catalogue'!L14 -> Active | I13: =IF(COUNTA(A13:H13)=8,"Complete","Incomplete") -> Complete | J13: =IF(G13<>"","Pass","Fail") -> Pass | K13: =IF(AND(C13<>"",D13<>"",E13<>""),"Pass","Fail") -> Pass | L13: =IF(AND(I13="Complete",J13="Pass",K13="Pass"),"Approved","Review Required") -> Approved
A14: ='Product Catalogue'!A15 -> OIL-COC-001 | B14: ='Product Catalogue'!B15 -> Crude Coconut Oil | C14: ='Product Catalogue'!C15 -> Oils & Fats | D14: ='Product Catalogue'!D15 -> Coconut Oil | E14: ='Product Catalogue'!E15 -> Virgin Oil | F14: ='Product Catalogue'!F15 -> Supplier D | G14: ='Product Catalogue'!G15 -> Virgin; Unrefined | H14: ='Product Catalogue'!L15 -> Active | I14: =IF(COUNTA(A14:H14)=8,"Complete","Incomplete") -> Complete | J14: =IF(G14<>"","Pass","Fail") -> Pass | K14: =IF(AND(C14<>"",D14<>"",E14<>""),"Pass","Fail") -> Pass | L14: =IF(AND(I14="Complete",J14="Pass",K14="Pass"),"Approved","Review Required") -> Approved
A15: ='Product Catalogue'!A16 -> SUG-ICU-001 | B15: ='Product Catalogue'!B16 -> ICUMSA 45 Sugar | C15: ='Product Catalogue'!C16 -> Food Commodities | D15: ='Product Catalogue'!D16 -> Sugar | E15: ='Product Catalogue'!E16 -> Refined White Sugar | F15: ='Product Catalogue'!F16 -> Supplier E | G15: ='Product Catalogue'!G16 -> White Refined; 50kg Bags | H15: ='Product Catalogue'!L16 -> Active | I15: =IF(COUNTA(A15:H15)=8,"Complete","Incomplete") -> Complete | J15: =IF(G15<>"","Pass","Fail") -> Pass | K15: =IF(AND(C15<>"",D15<>"",E15<>""),"Pass","Fail") -> Pass | L15: =IF(AND(I15="Complete",J15="Pass",K15="Pass"),"Approved","Review Required") -> Approved
A16: ='Product Catalogue'!A17 -> SUG-ICU-002 | B16: ='Product Catalogue'!B17 -> Refined White Sugar IC45 | C16: ='Product Catalogue'!C17 -> Food Commodities | D16: ='Product Catalogue'!D17 -> Sugar | E16: ='Product Catalogue'!E17 -> Refined White Sugar | F16: ='Product Catalogue'!F17 -> Supplier F | G16: ='Product Catalogue'!G17 -> White Refined; 50kg Bags | H16: ='Product Catalogue'!L17 -> Duplicate Review | I16: =IF(COUNTA(A16:H16)=8,"Complete","Incomplete") -> Complete | J16: =IF(G16<>"","Pass","Fail") -> Pass | K16: =IF(AND(C16<>"",D16<>"",E16<>""),"Pass","Fail") -> Pass | L16: =IF(AND(I16="Complete",J16="Pass",K16="Pass"),"Approved","Review Required") -> Approved
A17: ='Product Catalogue'!A18 -> SUG-ICU-003 | B17: ='Product Catalogue'!B18 -> ICUMSA 100 Sugar | C17: ='Product Catalogue'!C18 -> Food Commodities | D17: ='Product Catalogue'!D18 -> Sugar | E17: ='Product Catalogue'!E18 -> Refined White Sugar | F17: ='Product Catalogue'!F18 -> Supplier G | G17: ='Product Catalogue'!G18 -> White Refined; 50kg Bags | H17: ='Product Catalogue'!L18 -> Active | I17: =IF(COUNTA(A17:H17)=8,"Complete","Incomplete") -> Complete | J17: =IF(G17<>"","Pass","Fail") -> Pass | K17: =IF(AND(C17<>"",D17<>"",E17<>""),"Pass","Fail") -> Pass | L17: =IF(AND(I17="Complete",J17="Pass",K17="Pass"),"Approved","Review Required") -> Approved
A18: ='Product Catalogue'!A19 -> SUG-RAW-001 | B18: ='Product Catalogue'!B19 -> Raw Cane Sugar | C18: ='Product Catalogue'!C19 -> Food Commodities | D18: ='Product Catalogue'!D19 -> Sugar | E18: ='Product Catalogue'!E19 -> Raw Sugar | F18: ='Product Catalogue'!F19 -> Supplier H | G18: ='Product Catalogue'!G19 -> ICUMSA 600–1200 | H18: ='Product Catalogue'!L19 -> Active | I18: =IF(COUNTA(A18:H18)=8,"Complete","Incomplete") -> Complete | J18: =IF(G18<>"","Pass","Fail") -> Pass | K18: =IF(AND(C18<>"",D18<>"",E18<>""),"Pass","Fail") -> Pass | L18: =IF(AND(I18="Complete",J18="Pass",K18="Pass"),"Approved","Review Required") -> Approved
A19: ='Product Catalogue'!A20 -> RIC-WHI-001 | B19: ='Product Catalogue'!B20 -> Long Grain White Rice | C19: ='Product Catalogue'!C20 -> Food Commodities | D19: ='Product Catalogue'!D20 -> Rice | E19: ='Product Catalogue'!E20 -> Long Grain | F19: ='Product Catalogue'!F20 -> Supplier I | G19: ='Product Catalogue'!G20 -> 5% Broken; 25kg Bags | H19: ='Product Catalogue'!L20 -> Active | I19: =IF(COUNTA(A19:H19)=8,"Complete","Incomplete") -> Complete | J19: =IF(G19<>"","Pass","Fail") -> Pass | K19: =IF(AND(C19<>"",D19<>"",E19<>""),"Pass","Fail") -> Pass | L19: =IF(AND(I19="Complete",J19="Pass",K19="Pass"),"Approved","Review Required") -> Approved
... A51: ='Product Catalogue'!A52 -> LEG-SOY-001 | B51: ='Product Catalogue'!B52 -> Soybeans | C51: ='Product Catalogue'!C52 -> Food Commodities | D51: ='Product Catalogue'!D52 -> Legumes | E51: ='Product Catalogue'!E52 -> Soybeans | F51: ='Product Catalogue'!F52 -> Supplier A | G51: ='Product Catalogue'!G52 -> Non-GMO; Feed Grade | H51: ='Product Catalogue'!L52 -> Active | I51: =IF(COUNTA(A51:H51)=8,"Complete","Incomplete") -> Complete | J51: =IF(G51<>"","Pass","Fail") -> Pass | K51: =IF(AND(C51<>"",D51<>"",E51<>""),"Pass","Fail") -> Pass | L51: =IF(AND(I51="Complete",J51="Pass",K51="Pass"),"Approved","Review Required") -> Approved

Sheet Portfolio Overview
A1: Product Data Owner Portfolio
A3: Objective | B3: Demonstrate a structured product data management workflow
A4: Core Skills Demonstrated | B4: Product Catalogue, Taxonomy, Supplier Mapping, Duplicate Review, Data Quality, PIM Data Management
A5: Tools & Techniques | B5: Microsoft Excel, formulas, data validation, conditional formatting, lookup and reference formulas
A6: PIM Concepts | B6: Product Information Management, SKU mapping, taxonomy, supplier data, data quality and duplicate control
